[2022-05-16 07:23:58 +0000] [1337] [INFO] Starting gunicorn 20.1.0
[2022-05-16 07:23:58 +0000] [1337] [INFO] Listening at: http://0.0.0.0:8000 (1337)
[2022-05-16 07:23:58 +0000] [1337] [INFO] Using worker: sync
[2022-05-16 07:23:58 +0000] [1338] [INFO] Booting worker with pid: 1338
[2022-05-16 07:23:58 +0000] [1338] [ERROR] Exception in worker process
Traceback (most recent call last):
  File "/home/ubuntu/miniconda3/envs/sinor/lib/python3.9/site-packages/gunicorn/arbiter.py", line 589, in spawn_worker
    worker.init_process()
  File "/home/ubuntu/miniconda3/envs/sinor/lib/python3.9/site-packages/gunicorn/workers/base.py", line 134, in init_process
    self.load_wsgi()
  File "/home/ubuntu/miniconda3/envs/sinor/lib/python3.9/site-packages/gunicorn/workers/base.py", line 146, in load_wsgi
    self.wsgi = self.app.wsgi()
  File "/home/ubuntu/miniconda3/envs/sinor/lib/python3.9/site-packages/gunicorn/app/base.py", line 67, in wsgi
    self.callable = self.load()
  File "/home/ubuntu/miniconda3/envs/sinor/lib/python3.9/site-packages/gunicorn/app/wsgiapp.py", line 58, in load
    return self.load_wsgiapp()
  File "/home/ubuntu/miniconda3/envs/sinor/lib/python3.9/site-packages/gunicorn/app/wsgiapp.py", line 48, in load_wsgiapp
    return util.import_app(self.app_uri)
  File "/home/ubuntu/miniconda3/envs/sinor/lib/python3.9/site-packages/gunicorn/util.py", line 359, in import_app
    mod = importlib.import_module(module)
  File "/home/ubuntu/miniconda3/envs/sinor/lib/python3.9/importlib/__init__.py", line 127, in import_module
    return _bootstrap._gcd_import(name[level:], package, level)
  File "<frozen importlib._bootstrap>", line 1030, in _gcd_import
  File "<frozen importlib._bootstrap>", line 1007, in _find_and_load
  File "<frozen importlib._bootstrap>", line 972, in _find_and_load_unlocked
  File "<frozen importlib._bootstrap>", line 228, in _call_with_frames_removed
  File "<frozen importlib._bootstrap>", line 1030, in _gcd_import
  File "<frozen importlib._bootstrap>", line 1007, in _find_and_load
  File "<frozen importlib._bootstrap>", line 984, in _find_and_load_unlocked
ModuleNotFoundError: No module named 'sinor_Server'
[2022-05-16 07:23:58 +0000] [1338] [INFO] Worker exiting (pid: 1338)
[2022-05-16 07:23:58 +0000] [1337] [INFO] Shutting down: Master
[2022-05-16 07:23:58 +0000] [1337] [INFO] Reason: Worker failed to boot.
[2022-05-16 08:32:51 +0000] [1670] [INFO] Starting gunicorn 20.1.0
[2022-05-16 08:32:51 +0000] [1670] [INFO] Listening at: http://0.0.0.0:8000 (1670)
[2022-05-16 08:32:51 +0000] [1670] [INFO] Using worker: sync
[2022-05-16 08:32:51 +0000] [1671] [INFO] Booting worker with pid: 1671
[2022-05-16 08:32:51 +0000] [1671] [ERROR] Exception in worker process
Traceback (most recent call last):
  File "/home/ubuntu/miniconda3/envs/sinor/lib/python3.9/site-packages/gunicorn/arbiter.py", line 589, in spawn_worker
    worker.init_process()
  File "/home/ubuntu/miniconda3/envs/sinor/lib/python3.9/site-packages/gunicorn/workers/base.py", line 134, in init_process
    self.load_wsgi()
  File "/home/ubuntu/miniconda3/envs/sinor/lib/python3.9/site-packages/gunicorn/workers/base.py", line 146, in load_wsgi
    self.wsgi = self.app.wsgi()
  File "/home/ubuntu/miniconda3/envs/sinor/lib/python3.9/site-packages/gunicorn/app/base.py", line 67, in wsgi
    self.callable = self.load()
  File "/home/ubuntu/miniconda3/envs/sinor/lib/python3.9/site-packages/gunicorn/app/wsgiapp.py", line 58, in load
    return self.load_wsgiapp()
  File "/home/ubuntu/miniconda3/envs/sinor/lib/python3.9/site-packages/gunicorn/app/wsgiapp.py", line 48, in load_wsgiapp
    return util.import_app(self.app_uri)
  File "/home/ubuntu/miniconda3/envs/sinor/lib/python3.9/site-packages/gunicorn/util.py", line 359, in import_app
    mod = importlib.import_module(module)
  File "/home/ubuntu/miniconda3/envs/sinor/lib/python3.9/importlib/__init__.py", line 127, in import_module
    return _bootstrap._gcd_import(name[level:], package, level)
  File "<frozen importlib._bootstrap>", line 1030, in _gcd_import
  File "<frozen importlib._bootstrap>", line 1007, in _find_and_load
  File "<frozen importlib._bootstrap>", line 972, in _find_and_load_unlocked
  File "<frozen importlib._bootstrap>", line 228, in _call_with_frames_removed
  File "<frozen importlib._bootstrap>", line 1030, in _gcd_import
  File "<frozen importlib._bootstrap>", line 1007, in _find_and_load
  File "<frozen importlib._bootstrap>", line 984, in _find_and_load_unlocked
ModuleNotFoundError: No module named 'sinor_Server'
[2022-05-16 08:32:51 +0000] [1671] [INFO] Worker exiting (pid: 1671)
[2022-05-16 08:32:51 +0000] [1670] [INFO] Shutting down: Master
[2022-05-16 08:32:51 +0000] [1670] [INFO] Reason: Worker failed to boot.
[2022-05-16 08:32:53 +0000] [1672] [INFO] Starting gunicorn 20.1.0
[2022-05-16 08:32:53 +0000] [1672] [INFO] Listening at: http://0.0.0.0:8000 (1672)
[2022-05-16 08:32:53 +0000] [1672] [INFO] Using worker: sync
[2022-05-16 08:32:53 +0000] [1673] [INFO] Booting worker with pid: 1673
[2022-05-16 08:32:53 +0000] [1673] [ERROR] Exception in worker process
Traceback (most recent call last):
  File "/home/ubuntu/miniconda3/envs/sinor/lib/python3.9/site-packages/gunicorn/arbiter.py", line 589, in spawn_worker
    worker.init_process()
  File "/home/ubuntu/miniconda3/envs/sinor/lib/python3.9/site-packages/gunicorn/workers/base.py", line 134, in init_process
    self.load_wsgi()
  File "/home/ubuntu/miniconda3/envs/sinor/lib/python3.9/site-packages/gunicorn/workers/base.py", line 146, in load_wsgi
    self.wsgi = self.app.wsgi()
  File "/home/ubuntu/miniconda3/envs/sinor/lib/python3.9/site-packages/gunicorn/app/base.py", line 67, in wsgi
    self.callable = self.load()
  File "/home/ubuntu/miniconda3/envs/sinor/lib/python3.9/site-packages/gunicorn/app/wsgiapp.py", line 58, in load
    return self.load_wsgiapp()
  File "/home/ubuntu/miniconda3/envs/sinor/lib/python3.9/site-packages/gunicorn/app/wsgiapp.py", line 48, in load_wsgiapp
    return util.import_app(self.app_uri)
  File "/home/ubuntu/miniconda3/envs/sinor/lib/python3.9/site-packages/gunicorn/util.py", line 359, in import_app
    mod = importlib.import_module(module)
  File "/home/ubuntu/miniconda3/envs/sinor/lib/python3.9/importlib/__init__.py", line 127, in import_module
    return _bootstrap._gcd_import(name[level:], package, level)
  File "<frozen importlib._bootstrap>", line 1030, in _gcd_import
  File "<frozen importlib._bootstrap>", line 1007, in _find_and_load
  File "<frozen importlib._bootstrap>", line 972, in _find_and_load_unlocked
  File "<frozen importlib._bootstrap>", line 228, in _call_with_frames_removed
  File "<frozen importlib._bootstrap>", line 1030, in _gcd_import
  File "<frozen importlib._bootstrap>", line 1007, in _find_and_load
  File "<frozen importlib._bootstrap>", line 984, in _find_and_load_unlocked
ModuleNotFoundError: No module named 'sinor_Server'
[2022-05-16 08:32:53 +0000] [1673] [INFO] Worker exiting (pid: 1673)
[2022-05-16 08:32:53 +0000] [1672] [INFO] Shutting down: Master
[2022-05-16 08:32:53 +0000] [1672] [INFO] Reason: Worker failed to boot.
[2022-05-16 09:12:26 +0000] [1897] [INFO] Starting gunicorn 20.1.0
[2022-05-16 09:12:26 +0000] [1897] [INFO] Listening at: http://0.0.0.0:8000 (1897)
[2022-05-16 09:12:26 +0000] [1897] [INFO] Using worker: sync
[2022-05-16 09:12:26 +0000] [1898] [INFO] Booting worker with pid: 1898
[2022-05-16 09:12:26 +0000] [1898] [ERROR] Exception in worker process
Traceback (most recent call last):
  File "/home/ubuntu/miniconda3/envs/sinor/lib/python3.9/site-packages/gunicorn/arbiter.py", line 589, in spawn_worker
    worker.init_process()
  File "/home/ubuntu/miniconda3/envs/sinor/lib/python3.9/site-packages/gunicorn/workers/base.py", line 134, in init_process
    self.load_wsgi()
  File "/home/ubuntu/miniconda3/envs/sinor/lib/python3.9/site-packages/gunicorn/workers/base.py", line 146, in load_wsgi
    self.wsgi = self.app.wsgi()
  File "/home/ubuntu/miniconda3/envs/sinor/lib/python3.9/site-packages/gunicorn/app/base.py", line 67, in wsgi
    self.callable = self.load()
  File "/home/ubuntu/miniconda3/envs/sinor/lib/python3.9/site-packages/gunicorn/app/wsgiapp.py", line 58, in load
    return self.load_wsgiapp()
  File "/home/ubuntu/miniconda3/envs/sinor/lib/python3.9/site-packages/gunicorn/app/wsgiapp.py", line 48, in load_wsgiapp
    return util.import_app(self.app_uri)
  File "/home/ubuntu/miniconda3/envs/sinor/lib/python3.9/site-packages/gunicorn/util.py", line 359, in import_app
    mod = importlib.import_module(module)
  File "/home/ubuntu/miniconda3/envs/sinor/lib/python3.9/importlib/__init__.py", line 127, in import_module
    return _bootstrap._gcd_import(name[level:], package, level)
  File "<frozen importlib._bootstrap>", line 1030, in _gcd_import
  File "<frozen importlib._bootstrap>", line 1007, in _find_and_load
  File "<frozen importlib._bootstrap>", line 972, in _find_and_load_unlocked
  File "<frozen importlib._bootstrap>", line 228, in _call_with_frames_removed
  File "<frozen importlib._bootstrap>", line 1030, in _gcd_import
  File "<frozen importlib._bootstrap>", line 1007, in _find_and_load
  File "<frozen importlib._bootstrap>", line 984, in _find_and_load_unlocked
ModuleNotFoundError: No module named 'sinor_Server'
[2022-05-16 09:12:26 +0000] [1898] [INFO] Worker exiting (pid: 1898)
[2022-05-16 09:12:26 +0000] [1897] [INFO] Shutting down: Master
[2022-05-16 09:12:26 +0000] [1897] [INFO] Reason: Worker failed to boot.
[2022-05-16 09:12:31 +0000] [1899] [INFO] Starting gunicorn 20.1.0
[2022-05-16 09:12:31 +0000] [1899] [INFO] Listening at: http://0.0.0.0:8000 (1899)
[2022-05-16 09:12:31 +0000] [1899] [INFO] Using worker: sync
[2022-05-16 09:12:31 +0000] [1900] [INFO] Booting worker with pid: 1900
[2022-05-16 09:12:31 +0000] [1900] [ERROR] Exception in worker process
Traceback (most recent call last):
  File "/home/ubuntu/miniconda3/envs/sinor/lib/python3.9/site-packages/gunicorn/arbiter.py", line 589, in spawn_worker
    worker.init_process()
  File "/home/ubuntu/miniconda3/envs/sinor/lib/python3.9/site-packages/gunicorn/workers/base.py", line 134, in init_process
    self.load_wsgi()
  File "/home/ubuntu/miniconda3/envs/sinor/lib/python3.9/site-packages/gunicorn/workers/base.py", line 146, in load_wsgi
    self.wsgi = self.app.wsgi()
  File "/home/ubuntu/miniconda3/envs/sinor/lib/python3.9/site-packages/gunicorn/app/base.py", line 67, in wsgi
    self.callable = self.load()
  File "/home/ubuntu/miniconda3/envs/sinor/lib/python3.9/site-packages/gunicorn/app/wsgiapp.py", line 58, in load
    return self.load_wsgiapp()
  File "/home/ubuntu/miniconda3/envs/sinor/lib/python3.9/site-packages/gunicorn/app/wsgiapp.py", line 48, in load_wsgiapp
    return util.import_app(self.app_uri)
  File "/home/ubuntu/miniconda3/envs/sinor/lib/python3.9/site-packages/gunicorn/util.py", line 359, in import_app
    mod = importlib.import_module(module)
  File "/home/ubuntu/miniconda3/envs/sinor/lib/python3.9/importlib/__init__.py", line 127, in import_module
    return _bootstrap._gcd_import(name[level:], package, level)
  File "<frozen importlib._bootstrap>", line 1030, in _gcd_import
  File "<frozen importlib._bootstrap>", line 1007, in _find_and_load
  File "<frozen importlib._bootstrap>", line 972, in _find_and_load_unlocked
  File "<frozen importlib._bootstrap>", line 228, in _call_with_frames_removed
  File "<frozen importlib._bootstrap>", line 1030, in _gcd_import
  File "<frozen importlib._bootstrap>", line 1007, in _find_and_load
  File "<frozen importlib._bootstrap>", line 984, in _find_and_load_unlocked
ModuleNotFoundError: No module named 'sinor_Server'
[2022-05-16 09:12:31 +0000] [1900] [INFO] Worker exiting (pid: 1900)
[2022-05-16 09:12:31 +0000] [1899] [INFO] Shutting down: Master
[2022-05-16 09:12:31 +0000] [1899] [INFO] Reason: Worker failed to boot.
